<?xml version="1.0" ?>
<!-- =================================================================================== -->
<!-- |    This document was autogenerated by xacro from urdf/ur10_robot.urdf.xacro     | -->
<!-- |    EDITING THIS FILE BY HAND IS NOT RECOMMENDED                                 | -->
<!-- =================================================================================== -->
<robot name="ur10" xmlns:xacro="http://www.ros.org/wiki/xacro">
  
  <!-- ur10 -->
  <!-- arm -->
  <link name="world"/>
  <joint name="world_joint" type="fixed">
    <parent link="world"/>
    <child link="base_link"/>
    <origin rpy="0.0 0.0 0.0" xyz="0.0 0.0 0.0"/>
  </joint>
  
  <link name="base_link">
    <visual>
      <geometry>
        <mesh filename="visual/Base.dae"/>
      </geometry>
	  <material name="LightGrey">
          <color rgba="0.7 0.7 0.7 1.0"/>
      </material>
    </visual>
    <collision>
      <origin rpy="0 0 0" xyz="0.000 0.0 0.05"/>
      <geometry>
        <cylinder length="0.10" radius="0.085" />
        <!--<mesh filename="visual/Base.obj"/> -->
      </geometry>
    </collision>
    <collision>
      <origin rpy="0 0 0" xyz="0.0 0.0 0.135"/>
      <geometry>
        <cylinder length="0.155" radius="0.076" />
      </geometry>
    </collision>
    <inertial>
      <mass value="4.0"/>
      <origin rpy="0 0 0" xyz="0.0 0.0 0.0"/>
      <inertia ixx="0.0061063308908" ixy="0.0" ixz="0.0" iyy="0.0061063308908" iyz="0.0" izz="0.01125"/>
    </inertial>
  </link>
  
  <joint name="shoulder_pan_joint" type="revolute">
    <parent link="base_link"/>
    <child link="shoulder_link"/>
    <origin rpy="0.0 0.0 0.0" xyz="0.0 0.0 0.1273"/>
    <axis xyz="0 0 1"/>
    <limit effort="330.0" lower="-6.2831853" upper="6.2831853" velocity="2.16"/>
    <dynamics damping="0.0" friction="0.0"/>
  </joint>
  
  <link name="shoulder_link">
    <visual>
      <geometry>
        <mesh filename="visual/Shoulder.dae"/>
      </geometry>
	  <material name="LightGrey">
          <color rgba="0.7 0.7 0.7 1.0"/>
      </material>
    </visual>
    <collision>
      <origin rpy="1.57079632679 0 0" xyz="0.0 0.11 0.0"/>
      <geometry>
        <cylinder length="0.25" radius="0.074" />
        <!-- <mesh filename="Shoulder.obj"/>  -->
      </geometry>
    </collision>
    <inertial>
      <mass value="7.778"/>
      <origin rpy="0 0 0" xyz="0.0 0.0 0.0"/>
      <inertia ixx="0.0314743125769" ixy="0.0" ixz="0.0" iyy="0.0314743125769" iyz="0.0" izz="0.021875625"/>
    </inertial>
  </link>
  
  <joint name="shoulder_lift_joint" type="revolute">
    <parent link="shoulder_link"/>
    <child link="upper_arm_link"/>
    <origin rpy="0.0 1.570796325 0.0" xyz="0.0 0.220941 0.0"/>
    <axis xyz="0 1 0"/>
    <limit effort="330.0" lower="-6.2831853" upper="6.2831853" velocity="2.16"/>
    <dynamics damping="0.0" friction="0.0"/>
  </joint>
  
  <link name="upper_arm_link">
    <visual>
      <geometry>
        <mesh filename="visual/UpperArm.dae"/>
      </geometry>
	  <material name="LightGrey">
          <color rgba="0.7 0.7 0.7 1.0"/>
      </material>
    </visual>
    <collision>
      <origin rpy="0 0 0" xyz="0.0 -0.0500 0.305"/>
      <geometry>
        <cylinder length="0.65" radius="0.044" />
        <!-- <mesh filename="UpperArm.obj"/> -->
      </geometry>
    </collision>
	 <collision>
      <origin rpy="0 1.57 1.57" xyz="0 -0.04 0.61"/>
      <geometry>
        <cylinder length="0.125" radius="0.06" />
      </geometry>
    </collision>
    <inertial>
      <mass value="12.93"/>
      <origin rpy="0 0 0" xyz="0.0 0.0 0.306"/>
      <inertia ixx="0.421753803798" ixy="0.0" ixz="0.0" iyy="0.421753803798" iyz="0.0" izz="0.036365625"/>
    </inertial>
  </link>
  
  <joint name="elbow_joint" type="revolute">
    <parent link="upper_arm_link"/>
    <child link="forearm_link"/>
    <origin rpy="0.0 0.0 0.0" xyz="0.0 -0.1719 0.612"/>
    <axis xyz="0 1 0"/>
    <limit effort="150.0" lower="-6.2831853" upper="6.2831853" velocity="3.15"/>
    <dynamics damping="0.0" friction="0.0"/>
  </joint>
  <link name="forearm_link">
    <visual>
      <geometry>
        <mesh filename="visual/Forearm.dae"/>
      </geometry>
	  <material name="LightGrey">
          <color rgba="0.7 0.7 0.7 1.0"/>
      </material>
    </visual>
    <collision>
      <!-- <origin rpy="1.57079632679 0 0" xyz="0.0 0.00 -0.0"/> -->    
      <origin rpy="0 0 0" xyz="0 0.0 0.310"/>
      <geometry>
        <cylinder length="0.55" radius="0.044" />
        <!-- <mesh filename="Forearm.obj"/> -->
      </geometry>
    </collision>
    <collision>  
      <origin rpy="0 1.57 1.57" xyz="0 -0.003 0"/>
      <geometry>
        <cylinder length="0.13" radius="0.060" />
      </geometry>
    </collision>
    <inertial>
      <mass value="3.87"/>
      <origin rpy="0 0 0" xyz="0.0 0.0 0.28615"/>
      <inertia ixx="0.111069694097" ixy="0.0" ixz="0.0" iyy="0.111069694097" iyz="0.0" izz="0.010884375"/>
    </inertial>
  </link>
  
  <joint name="wrist_1_joint" type="revolute">
    <parent link="forearm_link"/>
    <child link="wrist_1_link"/>
    <origin rpy="0.0 1.570796325 0.0" xyz="0.0 0.0 0.5723"/>
    <axis xyz="0 1 0"/>
    <limit effort="54.0" lower="-6.2831853" upper="6.2831853" velocity="3.2"/>
    <dynamics damping="0.0" friction="0.0"/>
  </joint>
  
  <link name="wrist_1_link">
    <visual>
      <geometry>
        <mesh filename="visual/Wrist1.dae"/>
      </geometry>
	   <material name="LightGrey">
          <color rgba="0.7 0.7 0.7 1.0"/>
      </material>
    </visual>
    <collision>
      <origin rpy="0 0 0" xyz="0.0 0.1100 0.05"/>
      <geometry>
      
      <cylinder length="0.2" radius="0.044" />
        <!-- <mesh filename="Wrist1.obj"/> -->
      </geometry>
    </collision>
	<collision>
      <origin rpy="0 1.57 1.57" xyz="0 -0.003 0"/>
      <geometry>
        <cylinder length="0.13" radius="0.05" />
      </geometry>
    </collision>
    <inertial>
      <mass value="1.96"/>
      <origin rpy="0 0 0" xyz="0.0 0.0 0.0"/>
      <inertia ixx="0.0051082479567" ixy="0.0" ixz="0.0" iyy="0.0051082479567" iyz="0.0" izz="0.0055125"/>
    </inertial>
  </link>
  
  <joint name="wrist_2_joint" type="revolute">
    <parent link="wrist_1_link"/>
    <child link="wrist_2_link"/>
    <origin rpy="0.0 0.0 0.0" xyz="0.0 0.1149 0.0"/>
    <axis xyz="0 0 1"/>
    <limit effort="54.0" lower="-6.2831853" upper="6.2831853" velocity="3.2"/>
    <dynamics damping="0.0" friction="0.0"/>
  </joint>
  
  <link name="wrist_2_link">
    <visual>
      <geometry>
        <mesh filename="visual/Wrist2.dae"/>
      </geometry>
	  <material name="LightGrey">
          <color rgba="0.7 0.7 0.7 1.0"/>
      </material>
    </visual>
    <collision>
      <origin rpy="1.57079632679 0 0" xyz="0.0 0.035 0.115"/>
      <geometry>
      <cylinder length="0.11" radius="0.05" />
        <!-- <mesh filename="Wrist2.obj"/> -->
      </geometry>
    </collision>
    <inertial>
      <mass value="1.96"/>
      <origin rpy="0 0 0" xyz="0.0 0.0 0.0"/>
      <inertia ixx="0.0051082479567" ixy="0.0" ixz="0.0" iyy="0.0051082479567" iyz="0.0" izz="0.0055125"/>
    </inertial>
  </link>
  
  <joint name="wrist_3_joint" type="revolute">
    <parent link="wrist_2_link"/>
    <child link="wrist_3_link"/>
    <origin rpy="0.0 0.0 0.0" xyz="0.0 0.0 0.1157"/>
    <axis xyz="0 1 0"/>
    <limit effort="54.0" lower="-6.2831853" upper="6.2831853" velocity="3.2"/>
    <dynamics damping="0.0" friction="0.0"/>
  </joint>
  
  <link name="wrist_3_link">
    <visual>
      <geometry>
        <mesh filename="visual/Wrist3.dae"/>
      </geometry>
	   <material name="LightGrey">
          <color rgba="0.7 0.7 0.7 1.0"/>
      </material>
    </visual>
	
    <collision>
      <origin rpy="1.57079632679 0 0" xyz="0.0 0.10 0.0"/>
      <geometry>
        <cylinder length="0.025" radius="0.046" />
      </geometry>
    </collision>
  
    <inertial>
      <mass value="0.202"/>
      <origin rpy="0 0 0" xyz="0.0 0.0 0.0"/>
      <inertia ixx="0.000526462289415" ixy="0.0" ixz="0.0" iyy="0.000526462289415" iyz="0.0" izz="0.000568125"/>
    </inertial>
  </link>

  <joint name="robot_tool_joint" type="fixed">
    <origin rpy="-1.57079632679 0 0" xyz="0 0.2 0"/>
    <parent link="wrist_3_link"/>
    <child link="robot_tool_link"/>
  </joint>

<link name="robot_tool_link">
    <visual>
      <origin rpy="0 0 0" xyz="0 0 -0.1"/>
      <geometry>
         <cylinder radius="0.01" length="0.2"/>
      </geometry> 
      <material name="Red">
          <color rgba="0.2 0.05 0.05 1"/>
      </material>
    </visual>
    <collision>
      <origin rpy="0 0 0" xyz="0 0 -0.1"/>
      <geometry>
         <cylinder radius="0.01" length="0.2"/>
      </geometry>
    </collision>
    <inertial>
      <mass value="0"/>
      <origin rpy="0 0 0" xyz="0.0 0.0 0.0"/>
      <inertia ixx="0" ixy="0.0" ixz="0.0" iyy="0." iyz="0.0" izz="0"/>
    </inertial>
  </link>
  
</robot>
</robot>

